<?xml version="1.0" encoding="utf-8"?>
<!-- =================================================================================== -->
<!-- |    This document was autogenerated by xacro from lwr_tool.urdf.xacro            | -->
<!-- |    EDITING THIS FILE BY HAND IS NOT RECOMMENDED                                 | -->
<!-- =================================================================================== -->
<!-- Here we define the robot, we named it "lwr_tool" -->
<robot name="lwr_tool">
  <material name="Black">
    <color rgba="0.0 0.0 0.0 1.0"/>
  </material>
  <material name="Blue">
    <color rgba="0.0 0.0 0.8 1.0"/>
  </material>
  <material name="Green">
    <color rgba="0.0 0.8 0.0 1.0"/>
  </material>
  <material name="Grey">
    <color rgba="0.4 0.4 0.4 1.0"/>
  </material>
  <material name="Orange">
    <color rgba="1.0 0.423529411765 0.0392156862745 1.0"/>
  </material>
  <material name="Brown">
    <color rgba="0.870588235294 0.811764705882 0.764705882353 1.0"/>
  </material>
  <material name="Red">
    <color rgba="0.8 0.0 0.0 1.0"/>
  </material>
  <material name="White">
    <color rgba="1.0 1.0 1.0 1.0"/>
  </material>
  <material name="Kuka/DarkGrey">
    <color rgba="0.3 0.3 0.3 1.0"/>
  </material>
  <material name="Kuka/LightGrey">
    <color rgba="0.8 0.8 0.8 1.0"/>
  </material>
  <material name="Kuka/Red">
    <color rgba="0.3 0.3 0.3 1.0"/>
  </material>
  <material name="Kuka/Black">
    <color rgba="0 0 0 1.0"/>
  </material>
  <material name="Kuka/Orange">
    <color rgba="1.0 0.487 0 1.0"/>
  </material>
  <material name="Kuka/Silver">
    <color rgba="1.0 1.0 1.0 1.0"/>
  </material>
  <material name="Kuka/Grey">
    <color rgba="0.7 0.7 0.7 1.0"/>
  </material>
  <material name="Kuka/Blue">
    <color rgba="0.0 0.0 0.8 1.0"/>
  </material>
  <!-- reflex to stiffness -->
  <link name="world"/>
  <!-- First (shoulder) element of the arm. Fixed to its parent. -->
  <joint name="world_lwr_base_joint" type="fixed">
    <origin rpy="0 0 0" xyz="0 0 0"/>
    <origin rpy="0 0 0" xyz="0 0 0"/>
    <parent link="world"/>
    <child link="lwr_base_link"/>
  </joint>
  <link name="lwr_base_link">
    <inertial>
      <mass value="2.0"/>
      <origin xyz="0 0 0.055"/>
      <inertia ixx="0.00381666666667" ixy="0" ixz="0" iyy="0.0036" iyz="0" izz="0.00381666666667"/>
    </inertial>
    <visual>
      <origin rpy="0 0 3.14159265359" xyz="0 0 0"/>
      <geometry>
        <mesh filename="package://lwr_description/meshes/lwr4plus/visual/base.STL"/>
      </geometry>
      <material name="Kuka/Orange"/>
    </visual>
    <collision>
      <origin rpy="0 0 3.14159265359" xyz="0 0 0.055"/>
      <geometry>
        <cylinder length="0.11" radius="0.07"/>
      </geometry>
    </collision>
  </link>
  <!-- Second segment of the arm. Joint along z-axis -->
  <joint name="lwr_a1_joint" type="revolute">
    <origin rpy="0 0 0" xyz="0 0 0.11"/>
    <axis xyz="0 0 1"/>
    <limit effort="176" lower="-2.96705972839" upper="2.96705972839" velocity="1.91986217719"/>
    <!--	<dynamics friction="10.0" damping="1.0"/>-->
    <parent link="lwr_base_link"/>
    <child link="lwr_1_link"/>
  </joint>
  <link name="lwr_1_link">
    <inertial>
      <mass value="2.35"/>
      <origin rpy="0 0 0" xyz="0 -0.06 0.130"/>
      <inertia ixx="0.0160583333333" ixy="0" ixz="0" iyy="0.003525" iyz="0" izz="0.0139433333333"/>
    </inertial>
    <visual>
      <origin rpy="0 0 3.14159265359" xyz="0 0 -0.008"/>
      <geometry>
        <mesh filename="package://lwr_description/meshes/lwr4plus/visual/link_1.STL"/>
      </geometry>
      <material name="Kuka/Orange"/>
    </visual>
    <collision>
      <origin rpy="0 0 0" xyz="0 0 0.0"/>
      <geometry>
        <sphere radius="0.07"/>
      </geometry>
    </collision>
    <collision>
      <origin rpy="0 0 0" xyz="0 0.06 0.2"/>
      <geometry>
        <sphere radius="0.07"/>
      </geometry>
    </collision>
    <collision>
      <origin rpy="-0.291 0 0" xyz="0 0.03 0.1"/>
      <geometry>
        <cylinder length="0.208" radius="0.07"/>
      </geometry>
    </collision>
  </link>
  <!-- Third segment of the arm. Joint along y-axis -->
  <joint name="lwr_a2_joint" type="revolute">
    <origin rpy="0 0 0" xyz="0 0 0.2005"/>
    <axis xyz="0 -1 0"/>
    <limit effort="176" lower="-2.09439510239" upper="2.09439510239" velocity="1.91986217719"/>
    <!--	<dynamics friction="10.0" damping="1.0"/>-->
    <parent link="lwr_1_link"/>
    <child link="lwr_2_link"/>
  </joint>
  <link name="lwr_2_link">
    <inertial>
      <mass value="2.35"/>
      <origin rpy="0 0 0" xyz="0 0.06 0.07"/>
      <inertia ixx="0.0160583333333" ixy="0" ixz="0" iyy="0.003525" iyz="0" izz="0.0139433333333"/>
    </inertial>
    <visual>
      <origin rpy="0 0 3.14159265359" xyz="0 0 0.0"/>
      <geometry>
        <mesh filename="package://lwr_description/meshes/lwr4plus/visual/link_2.STL"/>
      </geometry>
      <material name="Kuka/Orange"/>
    </visual>
    <collision>
      <origin rpy="0 0 0" xyz="0 0 0.2"/>
      <geometry>
        <sphere radius="0.07"/>
      </geometry>
    </collision>
    <collision>
      <origin rpy="0 0 0" xyz="0 -0.06 0.0"/>
      <geometry>
        <sphere radius="0.07"/>
      </geometry>
    </collision>
    <collision>
      <origin rpy="-0.291 0 0" xyz="0 -0.03 0.1"/>
      <geometry>
        <cylinder length="0.208" radius="0.07"/>
      </geometry>
    </collision>
  </link>
  <!-- Fourth element of the arm. z-axis -->
  <joint name="lwr_e1_joint" type="revolute">
    <origin rpy="0 0 0" xyz="0 0 0.20"/>
    <axis xyz="0 0 1"/>
    <limit effort="100" lower="-2.96705972839" upper="2.96705972839" velocity="2.23402144255"/>
    <!--	<dynamics friction="10.0" damping="1.0"/>-->
    <parent link="lwr_2_link"/>
    <child link="lwr_3_link"/>
  </joint>
  <link name="lwr_3_link">
    <inertial>
      <mass value="2.35"/>
      <origin rpy="0 0 0" xyz="0 0.06 0.130"/>
      <inertia ixx="0.0160583333333" ixy="0" ixz="0" iyy="0.003525" iyz="0" izz="0.0139433333333"/>
    </inertial>
    <visual>
      <origin rpy="0 0 3.14159265359" xyz="0 0 -0.008"/>
      <geometry>
        <mesh filename="package://lwr_description/meshes/lwr4plus/visual/link_3.STL"/>
      </geometry>
      <material name="Kuka/Orange"/>
    </visual>
    <collision>
      <origin rpy="0 0 0" xyz="0 0 0.0"/>
      <geometry>
        <sphere radius="0.07"/>
      </geometry>
    </collision>
    <collision>
      <origin rpy="0 0 0" xyz="0 -0.06 0.2"/>
      <geometry>
        <sphere radius="0.07"/>
      </geometry>
    </collision>
    <collision>
      <origin rpy="0.291 0 0" xyz="0 -0.03 0.1"/>
      <geometry>
        <cylinder length="0.208" radius="0.07"/>
      </geometry>
    </collision>
  </link>
  <!-- fifth element of the arm. x-axis -->
  <joint name="lwr_a3_joint" type="revolute">
    <origin rpy="0 0 0" xyz="0 0 0.20"/>
    <axis xyz="0 1 0"/>
    <limit effort="100" lower="-2.09439510239" upper="2.09439510239" velocity="2.23402144255"/>
    <!--	<dynamics friction="10.0" damping="1.0"/>-->
    <parent link="lwr_3_link"/>
    <child link="lwr_4_link"/>
  </joint>
  <link name="lwr_4_link">
    <inertial>
      <mass value="2.35"/>
      <origin rpy="0 0 0" xyz="0 -0.06 0.07"/>
      <inertia ixx="0.0160583333333" ixy="0" ixz="0" iyy="0.003525" iyz="0" izz="0.0139433333333"/>
    </inertial>
    <visual>
      <origin rpy="0 0 3.14159265359" xyz="0 0 0.0"/>
      <geometry>
        <mesh filename="package://lwr_description/meshes/lwr4plus/visual/link_4.STL"/>
      </geometry>
      <material name="Kuka/Orange"/>
    </visual>
    <collision>
      <origin rpy="0 0 0" xyz="0 0 0.2"/>
      <geometry>
        <sphere radius="0.07"/>
      </geometry>
    </collision>
    <collision>
      <origin rpy="0 0 0" xyz="0 0.06 0.0"/>
      <geometry>
        <sphere radius="0.07"/>
      </geometry>
    </collision>
    <collision>
      <origin rpy="0.291 0 0" xyz="0 0.03 0.1"/>
      <geometry>
        <cylinder length="0.208" radius="0.07"/>
      </geometry>
    </collision>
  </link>
  <!-- Sixth element of the arm. z-axis -->
  <joint name="lwr_a4_joint" type="revolute">
    <origin rpy="0 0 0" xyz="0 0 0.20"/>
    <axis xyz="0 0 1"/>
    <limit effort="100" lower="-2.96705972839" upper="2.96705972839" velocity="3.56047167407"/>
    <!--	<dynamics friction="10.0" damping="1.0"/>-->
    <parent link="lwr_4_link"/>
    <child link="lwr_5_link"/>
  </joint>
  <link name="lwr_5_link">
    <inertial>
      <mass value="2.35"/>
      <origin rpy="0 0 0" xyz="0 0 0.124"/>
      <inertia ixx="0.0148645333333" ixy="0" ixz="0" iyy="0.003525" iyz="0" izz="0.0127495333333"/>
    </inertial>
    <visual>
      <origin rpy="0 0 3.14159265359" xyz="0 0 -0.008"/>
      <geometry name="lwr_5_geom">
        <mesh filename="package://lwr_description/meshes/lwr4plus/visual/link_5.STL"/>
      </geometry>
      <material name="Kuka/Orange"/>
    </visual>
    <collision>
      <origin rpy="0 0 0" xyz="0 0 0.0"/>
      <geometry>
        <sphere radius="0.07"/>
      </geometry>
    </collision>
    <collision>
      <origin rpy="0 0 0" xyz="0 0.04 0.19"/>
      <geometry>
        <sphere radius="0.07"/>
      </geometry>
    </collision>
    <collision>
      <origin rpy="-0.207 0 0" xyz="0 0.02 0.095"/>
      <geometry>
        <cylinder length="0.198" radius="0.07"/>
      </geometry>
    </collision>
  </link>
  <!-- Seventh element of the arm. z-axis -->
  <joint name="lwr_a5_joint" type="revolute">
    <origin rpy="0 0 0" xyz="0 0 0.19"/>
    <axis xyz="0 -1 0"/>
    <limit effort="38" lower="-2.09439510239" upper="2.09439510239" velocity="3.21140582367"/>
    <!--	<dynamics friction="10.0" damping="1.0"/>-->
    <parent link="lwr_5_link"/>
    <child link="lwr_6_link"/>
  </joint>
  <link name="lwr_6_link">
    <inertial>
      <mass value="1.1"/>
      <origin rpy="0 0 0" xyz="0 0 0.0625"/>
      <inertia ixx="0.00286458333333" ixy="0" ixz="0" iyy="0.00286458333333" iyz="0" izz="0.00286458333333"/>
    </inertial>
    <visual>
      <origin rpy="0 0 3.14159265359" xyz="0 0 0"/>
      <geometry>
        <mesh filename="package://lwr_description/meshes/lwr4plus/visual/link_6.STL"/>
      </geometry>
      <material name="Kuka/Grey"/>
    </visual>
    <collision>
      <origin rpy="0 0 3.14159265359" xyz="0 -0.01 0"/>
      <geometry>
        <sphere radius="0.08"/>
      </geometry>
    </collision>
  </link>
  <!-- Eighth element of the arm. z-axis -->
  <joint name="lwr_a6_joint" type="revolute">
    <origin rpy="0 0 0" xyz="0 0 0.078"/>
    <axis xyz="0 0 1"/>
    <limit effort="38" lower="-2.96705972839" upper="2.96705972839" velocity="3.21140582367"/>
    <!--	<dynamics friction="10.0" damping="1.0"/>-->
    <parent link="lwr_6_link"/>
    <child link="lwr_7_link"/>
  </joint>
  <link name="lwr_7_link">
    <inertial>
      <mass value="0.25"/>
      <origin xyz="0 0 0"/>
      <inertia ixx="0.000416666666667" ixy="0" ixz="0" iyy="0.000416666666667" iyz="0" izz="0.000416666666667"/>
    </inertial>
    <visual>
      <origin rpy="0 0 3.14159265359" xyz="0 0 0"/>
      <geometry>
        <mesh filename="package://lwr_description/meshes/lwr4plus/visual/link_7.STL"/>
      </geometry>
      <material name="Kuka/DarkGrey"/>
    </visual>
    <collision>
      <origin rpy="0 0 3.14159265359" xyz="0 0 0"/>
      <geometry>
        <cylinder length="0.05" radius="0.04"/>
      </geometry>
    </collision>
  </link>
  <gazebo>
    <!--		<plugin name="${name}_lwr_hw_sim" filename="liblwr_hw_gazebo_plugin.so">
				<robotNamespace>${name}</robotNamespace>
			</plugin> -->
    <plugin filename="libgazebo_ros_control.so" name="gazebo_ros_controller">
      <robotNamespace>lwr</robotNamespace>
    </plugin>
  </gazebo>
  <gazebo reference="lwr_base_link">
    <gravity>true</gravity>
    <material>Gazebo/Orange</material>
  </gazebo>
  <gazebo reference="lwr_1_link">
    <gravity>true</gravity>
    <material>Gazebo/Orange</material>
  </gazebo>
  <gazebo reference="lwr_2_link">
    <gravity>true</gravity>
    <material>Gazebo/Orange</material>
  </gazebo>
  <gazebo reference="lwr_3_link">
    <gravity>true</gravity>
    <material>Gazebo/Orange</material>
  </gazebo>
  <gazebo reference="lwr_4_link">
    <gravity>true</gravity>
    <material>Gazebo/Orange</material>
  </gazebo>
  <gazebo reference="lwr_5_link">
    <gravity>true</gravity>
    <material>Gazebo/Orange</material>
  </gazebo>
  <gazebo reference="lwr_6_link">
    <gravity>true</gravity>
    <material>Gazebo/Orange</material>
  </gazebo>
  <gazebo reference="lwr_7_link">
    <gravity>true</gravity>
    <material>Gazebo/Grey</material>
  </gazebo>
  <transmission name="lwr_a1_trans">
    <type>transmission_interface/SimpleTransmission</type>
    <joint name="lwr_a1_joint">
      <hardwareInterface>hardware_interface/EffortJointInterface</hardwareInterface>
    </joint>
    <actuator name="lwr_a1_motor">
      <hardwareInterface>hardware_interface/EffortJointInterface</hardwareInterface>
      <mechanicalReduction>1</mechanicalReduction>
    </actuator>
  </transmission>
  <transmission name="lwr_a2_trans">
    <type>transmission_interface/SimpleTransmission</type>
    <joint name="lwr_a2_joint">
      <hardwareInterface>hardware_interface/EffortJointInterface</hardwareInterface>
    </joint>
    <actuator name="lwr_a2_motor">
      <hardwareInterface>hardware_interface/EffortJointInterface</hardwareInterface>
      <mechanicalReduction>1</mechanicalReduction>
    </actuator>
  </transmission>
  <transmission name="lwr_e1_trans">
    <type>transmission_interface/SimpleTransmission</type>
    <joint name="lwr_e1_joint">
      <hardwareInterface>hardware_interface/EffortJointInterface</hardwareInterface>
    </joint>
    <actuator name="lwr_e1_motor">
      <hardwareInterface>hardware_interface/EffortJointInterface</hardwareInterface>
      <mechanicalReduction>1</mechanicalReduction>
    </actuator>
  </transmission>
  <transmission name="lwr_a3_trans">
    <type>transmission_interface/SimpleTransmission</type>
    <joint name="lwr_a3_joint">
      <hardwareInterface>hardware_interface/EffortJointInterface</hardwareInterface>
    </joint>
    <actuator name="lwr_a3_motor">
      <hardwareInterface>hardware_interface/EffortJointInterface</hardwareInterface>
      <mechanicalReduction>1</mechanicalReduction>
    </actuator>
  </transmission>
  <transmission name="lwr_a4_trans">
    <type>transmission_interface/SimpleTransmission</type>
    <joint name="lwr_a4_joint">
      <hardwareInterface>hardware_interface/EffortJointInterface</hardwareInterface>
    </joint>
    <actuator name="lwr_a4_motor">
      <hardwareInterface>hardware_interface/EffortJointInterface</hardwareInterface>
      <mechanicalReduction>1</mechanicalReduction>
    </actuator>
  </transmission>
  <transmission name="lwr_a5_trans">
    <type>transmission_interface/SimpleTransmission</type>
    <joint name="lwr_a5_joint">
      <hardwareInterface>hardware_interface/EffortJointInterface</hardwareInterface>
    </joint>
    <actuator name="lwr_a5_motor">
      <hardwareInterface>hardware_interface/EffortJointInterface</hardwareInterface>
      <mechanicalReduction>1</mechanicalReduction>
    </actuator>
  </transmission>
  <transmission name="lwr_a6_trans">
    <type>transmission_interface/SimpleTransmission</type>
    <joint name="lwr_a6_joint">
      <hardwareInterface>hardware_interface/EffortJointInterface</hardwareInterface>
    </joint>
    <actuator name="lwr_a6_motor">
      <hardwareInterface>hardware_interface/EffortJointInterface</hardwareInterface>
      <mechanicalReduction>1</mechanicalReduction>
    </actuator>
  </transmission>
  <!--  Define the origin of your 3D space
  Here we define a box lying at 0,0,0 with some dimensions, in reality our robot is place on top of a metal cart with those dimensions.
  This will include the cart in the scene and avoid the robot to hit it when using MoveIt!
  If you don't want to have that you can define a basic world link (see commented lines)
  -->
  <!--
  <link name="world"/>

  <link name="world">
    <visual>
      <origin xyz="0 0 0.42" rpy="0 0 0"/>
      <geometry>
	<box size="0.68 0.605 0.84"/>
      </geometry>
    </visual>
    <collision>
      <origin xyz="0 0 0.42" rpy="0 0 0"/>
      <geometry>
	<box size="0.68 0.605 0.84"/>
      </geometry>
    </collision>
  </link>
-->
  <gazebo reference="world">
    <static>true</static>
  </gazebo>
  <!-- The ft_sensor plugin
  <gazebo reference="tool_tip_joint">
      <provideFeedback>true</provideFeedback>
     <disableFixedJointLumping>true</disableFixedJointLumping>
  </gazebo>
  <gazebo>
      <plugin name="ft_sensor" filename="libgazebo_ros_ft_sensor.so">
          <updateRate>500.0</updateRate>
          <topicName>ft_sensor_topic</topicName>
          <jointName>tool_tip_joint</jointName>
      </plugin>
  </gazebo>-->
  <!-- Here we insert an iiwa7 robot in the scene, it's origin is just on top of the box previously defined. You can use 0,0,0 if you don't have that. -->
  <!--  <xacro:single_lwr_robot hardware_interface="$(arg hardware_interface)" robot_name="$(arg robot_name)" parent="world">
   <origin xyz="0 0 0.84" rpy="0 0 0"/>
    <origin xyz="0 0 0" rpy="0 0 0"/>
  </xacro:single_lwr_robot> -->
  <!--  Here we define a dummy joint between the tip of the iiwa7 and the base of the tool.
  There is no offset between the two, that means the tool is attached at the robot flange. -->
  <joint name="tool_joint" type="fixed">
    <parent link="lwr_7_link"/>
    <child link="tool_link"/>
    <origin rpy="0 0 0" xyz="0.00 0.00 0.00"/>
  </joint>
  <!-- Here we define the geometry of the tool. We designed the tool ourselves, so we have a mesh file that represents it.
  Else, one can define it using a geometric representation that approximate it, like a cylinder (see commented lines) -->
  <link name="tool_link">
    <visual>
      <origin rpy="0 0 0" xyz="0 0 0"/>
      <geometry>
        <mesh filename="package://lwr_end_eff/meshes/visual/tool.stl"/>
        <!-- 	<cylinder length="0.1275" radius="0.020"/> -->
      </geometry>
      <material name="Grey"/>
    </visual>
    <collision name="tool_link_collision">
      <origin rpy="0 0 0" xyz="0 0 0"/>
      <geometry>
        <mesh filename="package://lwr_end_eff/meshes/visual/tool.stl"/>
        <!-- 	<cylinder length="0.1275" radius="0.020"/> -->
      </geometry>
      <material name="Grey"/>
    </collision>
  </link>
  <!--  Here we define another dummy joint. It is placed at the end of the tool, so we can then attach a frame at its TCP for control -->
  <joint name="tool_tip_joint" type="fixed">
    <parent link="tool_link"/>
    <child link="tool_link_ee"/>
    <origin rpy="0 0 0" xyz="0.00 0.00 0.1275"/>
  </joint>
  <!--  The TCP frame is here defined -->
  <link name="tool_link_ee"/>
  <gazebo reference="tool_link">
    <sensor name="my_contact" type="contact">
      <plugin filename="libcontact.so" name="my_plugin">
        <alwaysOn>true</alwaysOn>
        <updateRate>500</updateRate>
        <bumperTopicName>bumper</bumperTopicName>
        <frameName>tool_link</frameName>
      </plugin>
      <contact>
        <collision>tool_link_collision_collision</collision>
      </contact>
      <update_rate> 500 </update_rate>
    </sensor>
  </gazebo>
  <gazebo reference="tool_link">
    <sensor name="gripper_contact_sensor" type="contact">
      <always_on>true</always_on>
      <update_rate>500.0</update_rate>
      <contact>
        <collision>tool_link_collision_collision</collision>
      </contact>
      <plugin filename="libgazebo_ros_bumper.so" name="gripper_bumper">
        <bumperTopicName>gripper_contact_sensor_state</bumperTopicName>
        <frameName>tool_link</frameName>
      </plugin>
    </sensor>
  </gazebo>
</robot>
