<sdf version='1.6'>
  <model name='lwr_tool'>
    <link name='lwr_base_link'>
      <pose frame=''>0 0 0 0 -0 0</pose>
      <inertial>
        <pose frame=''>0 0 0.055 0 -0 0</pose>
        <mass>2</mass>
        <inertia>
          <ixx>0.00381667</ixx>
          <ixy>0</ixy>
          <ixz>0</ixz>
          <iyy>0.0036</iyy>
          <iyz>0</iyz>
          <izz>0.00381667</izz>
        </inertia>
      </inertial>
      <collision name='lwr_base_link_collision'>
        <pose frame=''>0 0 0.055 0 -0 -3.14159</pose>
        <geometry>
          <cylinder>
            <length>0.11</length>
            <radius>0.07</radius>
          </cylinder>
        </geometry>
        <surface>
          <contact>
            <ode/>
          </contact>
          <friction>
            <ode/>
          </friction>
        </surface>
      </collision>
      <visual name='lwr_base_link_visual'>
        <pose frame=''>0 0 0 0 -0 -3.14159</pose>
        <geometry>
          <mesh>
            <scale>1 1 1</scale>
            <uri>model://lwr_description/meshes/lwr4plus/visual/base.STL</uri>
          </mesh>
        </geometry>
        <material>
          <script>
            <name>Gazebo/Orange</name>
            <uri>file://media/materials/scripts/gazebo.material</uri>
          </script>
        </material>
      </visual>
      <gravity>1</gravity>
      <velocity_decay/>
      <gravity>1</gravity>
    </link>
    <joint name='world_lwr_base_joint' type='fixed'>
      <child>lwr_base_link</child>
      <parent>world</parent>
    </joint>
    <link name='lwr_1_link'>
      <pose frame=''>0 0 0.11 0 -0 0</pose>
      <inertial>
        <pose frame=''>0 -0.06 0.13 0 -0 0</pose>
        <mass>2.35</mass>
        <inertia>
          <ixx>0.0160583</ixx>
          <ixy>0</ixy>
          <ixz>0</ixz>
          <iyy>0.003525</iyy>
          <iyz>0</iyz>
          <izz>0.0139433</izz>
        </inertia>
      </inertial>
      <collision name='lwr_1_link_collision'>
        <pose frame=''>0 0 0 0 -0 0</pose>
        <geometry>
          <sphere>
            <radius>0.07</radius>
          </sphere>
        </geometry>
        <surface>
          <contact>
            <ode/>
          </contact>
          <friction>
            <ode/>
          </friction>
        </surface>
      </collision>
      <collision name='lwr_1_link_collision_1'>
        <pose frame=''>0 0.06 0.2 0 -0 0</pose>
        <geometry>
          <sphere>
            <radius>0.07</radius>
          </sphere>
        </geometry>
        <surface>
          <contact>
            <ode/>
          </contact>
          <friction>
            <ode/>
          </friction>
        </surface>
      </collision>
      <collision name='lwr_1_link_collision_2'>
        <pose frame=''>0 0.03 0.1 -0.291 0 0</pose>
        <geometry>
          <cylinder>
            <length>0.208</length>
            <radius>0.07</radius>
          </cylinder>
        </geometry>
        <surface>
          <contact>
            <ode/>
          </contact>
          <friction>
            <ode/>
          </friction>
        </surface>
      </collision>
      <visual name='lwr_1_link_visual'>
        <pose frame=''>0 0 -0.008 0 -0 -3.14159</pose>
        <geometry>
          <mesh>
            <scale>1 1 1</scale>
            <uri>model://lwr_description/meshes/lwr4plus/visual/link_1.STL</uri>
          </mesh>
        </geometry>
        <material>
          <script>
            <name>Gazebo/Orange</name>
            <uri>file://media/materials/scripts/gazebo.material</uri>
          </script>
        </material>
      </visual>
      <gravity>1</gravity>
      <velocity_decay/>
      <gravity>1</gravity>
    </link>
    <joint name='lwr_a1_joint' type='revolute'>
      <child>lwr_1_link</child>
      <parent>lwr_base_link</parent>
      <axis>
        <xyz>0 0 1</xyz>
        <limit>
          <lower>-2.96706</lower>
          <upper>2.96706</upper>
          <effort>176</effort>
          <velocity>1.91986</velocity>
        </limit>
        <dynamics>
          <spring_reference>0</spring_reference>
          <spring_stiffness>0</spring_stiffness>
        </dynamics>
        <use_parent_model_frame>1</use_parent_model_frame>
      </axis>
    </joint>
    <link name='lwr_2_link'>
      <pose frame=''>0 0 0.3105 0 -0 0</pose>
      <inertial>
        <pose frame=''>0 0.06 0.07 0 -0 0</pose>
        <mass>2.35</mass>
        <inertia>
          <ixx>0.0160583</ixx>
          <ixy>0</ixy>
          <ixz>0</ixz>
          <iyy>0.003525</iyy>
          <iyz>0</iyz>
          <izz>0.0139433</izz>
        </inertia>
      </inertial>
      <collision name='lwr_2_link_collision'>
        <pose frame=''>0 0 0.2 0 -0 0</pose>
        <geometry>
          <sphere>
            <radius>0.07</radius>
          </sphere>
        </geometry>
        <surface>
          <contact>
            <ode/>
          </contact>
          <friction>
            <ode/>
          </friction>
        </surface>
      </collision>
      <collision name='lwr_2_link_collision_1'>
        <pose frame=''>0 -0.06 0 0 -0 0</pose>
        <geometry>
          <sphere>
            <radius>0.07</radius>
          </sphere>
        </geometry>
        <surface>
          <contact>
            <ode/>
          </contact>
          <friction>
            <ode/>
          </friction>
        </surface>
      </collision>
      <collision name='lwr_2_link_collision_2'>
        <pose frame=''>0 -0.03 0.1 -0.291 0 0</pose>
        <geometry>
          <cylinder>
            <length>0.208</length>
            <radius>0.07</radius>
          </cylinder>
        </geometry>
        <surface>
          <contact>
            <ode/>
          </contact>
          <friction>
            <ode/>
          </friction>
        </surface>
      </collision>
      <visual name='lwr_2_link_visual'>
        <pose frame=''>0 0 0 0 -0 -3.14159</pose>
        <geometry>
          <mesh>
            <scale>1 1 1</scale>
            <uri>model://lwr_description/meshes/lwr4plus/visual/link_2.STL</uri>
          </mesh>
        </geometry>
        <material>
          <script>
            <name>Gazebo/Orange</name>
            <uri>file://media/materials/scripts/gazebo.material</uri>
          </script>
        </material>
      </visual>
      <gravity>1</gravity>
      <velocity_decay/>
      <gravity>1</gravity>
    </link>
    <joint name='lwr_a2_joint' type='revolute'>
      <child>lwr_2_link</child>
      <parent>lwr_1_link</parent>
      <axis>
        <xyz>0 -1 0</xyz>
        <limit>
          <lower>-2.0944</lower>
          <upper>2.0944</upper>
          <effort>176</effort>
          <velocity>1.91986</velocity>
        </limit>
        <dynamics>
          <spring_reference>0</spring_reference>
          <spring_stiffness>0</spring_stiffness>
        </dynamics>
        <use_parent_model_frame>1</use_parent_model_frame>
      </axis>
    </joint>
    <link name='lwr_3_link'>
      <pose frame=''>0 0 0.5105 0 -0 0</pose>
      <inertial>
        <pose frame=''>0 0.06 0.13 0 -0 0</pose>
        <mass>2.35</mass>
        <inertia>
          <ixx>0.0160583</ixx>
          <ixy>0</ixy>
          <ixz>0</ixz>
          <iyy>0.003525</iyy>
          <iyz>0</iyz>
          <izz>0.0139433</izz>
        </inertia>
      </inertial>
      <collision name='lwr_3_link_collision'>
        <pose frame=''>0 0 0 0 -0 0</pose>
        <geometry>
          <sphere>
            <radius>0.07</radius>
          </sphere>
        </geometry>
        <surface>
          <contact>
            <ode/>
          </contact>
          <friction>
            <ode/>
          </friction>
        </surface>
      </collision>
      <collision name='lwr_3_link_collision_1'>
        <pose frame=''>0 -0.06 0.2 0 -0 0</pose>
        <geometry>
          <sphere>
            <radius>0.07</radius>
          </sphere>
        </geometry>
        <surface>
          <contact>
            <ode/>
          </contact>
          <friction>
            <ode/>
          </friction>
        </surface>
      </collision>
      <collision name='lwr_3_link_collision_2'>
        <pose frame=''>0 -0.03 0.1 0.291 -0 0</pose>
        <geometry>
          <cylinder>
            <length>0.208</length>
            <radius>0.07</radius>
          </cylinder>
        </geometry>
        <surface>
          <contact>
            <ode/>
          </contact>
          <friction>
            <ode/>
          </friction>
        </surface>
      </collision>
      <visual name='lwr_3_link_visual'>
        <pose frame=''>0 0 -0.008 0 -0 -3.14159</pose>
        <geometry>
          <mesh>
            <scale>1 1 1</scale>
            <uri>model://lwr_description/meshes/lwr4plus/visual/link_3.STL</uri>
          </mesh>
        </geometry>
        <material>
          <script>
            <name>Gazebo/Orange</name>
            <uri>file://media/materials/scripts/gazebo.material</uri>
          </script>
        </material>
      </visual>
      <gravity>1</gravity>
      <velocity_decay/>
      <gravity>1</gravity>
    </link>
    <joint name='lwr_e1_joint' type='revolute'>
      <child>lwr_3_link</child>
      <parent>lwr_2_link</parent>
      <axis>
        <xyz>0 0 1</xyz>
        <limit>
          <lower>-2.96706</lower>
          <upper>2.96706</upper>
          <effort>100</effort>
          <velocity>2.23402</velocity>
        </limit>
        <dynamics>
          <spring_reference>0</spring_reference>
          <spring_stiffness>0</spring_stiffness>
        </dynamics>
        <use_parent_model_frame>1</use_parent_model_frame>
      </axis>
    </joint>
    <link name='lwr_4_link'>
      <pose frame=''>0 0 0.7105 0 -0 0</pose>
      <inertial>
        <pose frame=''>0 -0.06 0.07 0 -0 0</pose>
        <mass>2.35</mass>
        <inertia>
          <ixx>0.0160583</ixx>
          <ixy>0</ixy>
          <ixz>0</ixz>
          <iyy>0.003525</iyy>
          <iyz>0</iyz>
          <izz>0.0139433</izz>
        </inertia>
      </inertial>
      <collision name='lwr_4_link_collision'>
        <pose frame=''>0 0 0.2 0 -0 0</pose>
        <geometry>
          <sphere>
            <radius>0.07</radius>
          </sphere>
        </geometry>
        <surface>
          <contact>
            <ode/>
          </contact>
          <friction>
            <ode/>
          </friction>
        </surface>
      </collision>
      <collision name='lwr_4_link_collision_1'>
        <pose frame=''>0 0.06 0 0 -0 0</pose>
        <geometry>
          <sphere>
            <radius>0.07</radius>
          </sphere>
        </geometry>
        <surface>
          <contact>
            <ode/>
          </contact>
          <friction>
            <ode/>
          </friction>
        </surface>
      </collision>
      <collision name='lwr_4_link_collision_2'>
        <pose frame=''>0 0.03 0.1 0.291 -0 0</pose>
        <geometry>
          <cylinder>
            <length>0.208</length>
            <radius>0.07</radius>
          </cylinder>
        </geometry>
        <surface>
          <contact>
            <ode/>
          </contact>
          <friction>
            <ode/>
          </friction>
        </surface>
      </collision>
      <visual name='lwr_4_link_visual'>
        <pose frame=''>0 0 0 0 -0 -3.14159</pose>
        <geometry>
          <mesh>
            <scale>1 1 1</scale>
            <uri>model://lwr_description/meshes/lwr4plus/visual/link_4.STL</uri>
          </mesh>
        </geometry>
        <material>
          <script>
            <name>Gazebo/Orange</name>
            <uri>file://media/materials/scripts/gazebo.material</uri>
          </script>
        </material>
      </visual>
      <gravity>1</gravity>
      <velocity_decay/>
      <gravity>1</gravity>
    </link>
    <joint name='lwr_a3_joint' type='revolute'>
      <child>lwr_4_link</child>
      <parent>lwr_3_link</parent>
      <axis>
        <xyz>0 1 0</xyz>
        <limit>
          <lower>-2.0944</lower>
          <upper>2.0944</upper>
          <effort>100</effort>
          <velocity>2.23402</velocity>
        </limit>
        <dynamics>
          <spring_reference>0</spring_reference>
          <spring_stiffness>0</spring_stiffness>
        </dynamics>
        <use_parent_model_frame>1</use_parent_model_frame>
      </axis>
    </joint>
    <link name='lwr_5_link'>
      <pose frame=''>0 0 0.9105 0 -0 0</pose>
      <inertial>
        <pose frame=''>0 0 0.124 0 -0 0</pose>
        <mass>2.35</mass>
        <inertia>
          <ixx>0.0148645</ixx>
          <ixy>0</ixy>
          <ixz>0</ixz>
          <iyy>0.003525</iyy>
          <iyz>0</iyz>
          <izz>0.0127495</izz>
        </inertia>
      </inertial>
      <collision name='lwr_5_link_collision'>
        <pose frame=''>0 0 0 0 -0 0</pose>
        <geometry>
          <sphere>
            <radius>0.07</radius>
          </sphere>
        </geometry>
        <surface>
          <contact>
            <ode/>
          </contact>
          <friction>
            <ode/>
          </friction>
        </surface>
      </collision>
      <collision name='lwr_5_link_collision_1'>
        <pose frame=''>0 0.04 0.19 0 -0 0</pose>
        <geometry>
          <sphere>
            <radius>0.07</radius>
          </sphere>
        </geometry>
        <surface>
          <contact>
            <ode/>
          </contact>
          <friction>
            <ode/>
          </friction>
        </surface>
      </collision>
      <collision name='lwr_5_link_collision_2'>
        <pose frame=''>0 0.02 0.095 -0.207 0 0</pose>
        <geometry>
          <cylinder>
            <length>0.198</length>
            <radius>0.07</radius>
          </cylinder>
        </geometry>
        <surface>
          <contact>
            <ode/>
          </contact>
          <friction>
            <ode/>
          </friction>
        </surface>
      </collision>
      <visual name='lwr_5_link_visual'>
        <pose frame=''>0 0 -0.008 0 -0 -3.14159</pose>
        <geometry>
          <mesh>
            <scale>1 1 1</scale>
            <uri>model://lwr_description/meshes/lwr4plus/visual/link_5.STL</uri>
          </mesh>
        </geometry>
        <material>
          <script>
            <name>Gazebo/Orange</name>
            <uri>file://media/materials/scripts/gazebo.material</uri>
          </script>
        </material>
      </visual>
      <gravity>1</gravity>
      <velocity_decay/>
      <gravity>1</gravity>
    </link>
    <joint name='lwr_a4_joint' type='revolute'>
      <child>lwr_5_link</child>
      <parent>lwr_4_link</parent>
      <axis>
        <xyz>0 0 1</xyz>
        <limit>
          <lower>-2.96706</lower>
          <upper>2.96706</upper>
          <effort>100</effort>
          <velocity>3.56047</velocity>
        </limit>
        <dynamics>
          <spring_reference>0</spring_reference>
          <spring_stiffness>0</spring_stiffness>
        </dynamics>
        <use_parent_model_frame>1</use_parent_model_frame>
      </axis>
    </joint>
    <link name='lwr_6_link'>
      <pose frame=''>0 0 1.1005 0 -0 0</pose>
      <inertial>
        <pose frame=''>0 0 0.0625 0 -0 0</pose>
        <mass>1.1</mass>
        <inertia>
          <ixx>0.00286458</ixx>
          <ixy>0</ixy>
          <ixz>0</ixz>
          <iyy>0.00286458</iyy>
          <iyz>0</iyz>
          <izz>0.00286458</izz>
        </inertia>
      </inertial>
      <collision name='lwr_6_link_collision'>
        <pose frame=''>0 -0.01 0 0 -0 -3.14159</pose>
        <geometry>
          <sphere>
            <radius>0.08</radius>
          </sphere>
        </geometry>
        <surface>
          <contact>
            <ode/>
          </contact>
          <friction>
            <ode/>
          </friction>
        </surface>
      </collision>
      <visual name='lwr_6_link_visual'>
        <pose frame=''>0 0 0 0 -0 -3.14159</pose>
        <geometry>
          <mesh>
            <scale>1 1 1</scale>
            <uri>model://lwr_description/meshes/lwr4plus/visual/link_6.STL</uri>
          </mesh>
        </geometry>
        <material>
          <script>
            <name>Gazebo/Orange</name>
            <uri>file://media/materials/scripts/gazebo.material</uri>
          </script>
        </material>
      </visual>
      <gravity>1</gravity>
      <velocity_decay/>
      <gravity>1</gravity>
    </link>
    <joint name='lwr_a5_joint' type='revolute'>
      <child>lwr_6_link</child>
      <parent>lwr_5_link</parent>
      <axis>
        <xyz>0 -1 0</xyz>
        <limit>
          <lower>-2.0944</lower>
          <upper>2.0944</upper>
          <effort>38</effort>
          <velocity>3.21141</velocity>
        </limit>
        <dynamics>
          <spring_reference>0</spring_reference>
          <spring_stiffness>0</spring_stiffness>
        </dynamics>
        <use_parent_model_frame>1</use_parent_model_frame>
      </axis>
    </joint>
    <link name='lwr_7_link'>
      <pose frame=''>0 0 1.1785 0 -0 0</pose>
      <inertial>
        <pose frame=''>0 0 0 0 -0 0</pose>
        <mass>0.25</mass>
        <inertia>
          <ixx>0.000416667</ixx>
          <ixy>0</ixy>
          <ixz>0</ixz>
          <iyy>0.000416667</iyy>
          <iyz>0</iyz>
          <izz>0.000416667</izz>
        </inertia>
      </inertial>
      <collision name='lwr_7_link_collision'>
        <pose frame=''>0 0 0 0 -0 -3.14159</pose>
        <geometry>
          <cylinder>
            <length>0.05</length>
            <radius>0.04</radius>
          </cylinder>
        </geometry>
        <surface>
          <contact>
            <ode/>
          </contact>
          <friction>
            <ode/>
          </friction>
        </surface>
      </collision>
      <collision name='lwr_7_link_fixed_joint_lump__tool_link_collision_collision_1'>
        <pose frame=''>0 0 0 0 -0 0</pose>
        <geometry>
          <mesh>
            <scale>1 1 1</scale>
            <uri>model://lwr_end_eff/meshes/visual/tool.stl</uri>
          </mesh>
        </geometry>
        <surface>
          <contact>
            <ode/>
          </contact>
          <friction>
            <ode/>
          </friction>
        </surface>
      </collision>
      <visual name='lwr_7_link_visual'>
        <pose frame=''>0 0 0 0 -0 -3.14159</pose>
        <geometry>
          <mesh>
            <scale>1 1 1</scale>
            <uri>model://lwr_description/meshes/lwr4plus/visual/link_7.STL</uri>
          </mesh>
        </geometry>
        <material>
          <script>
            <name>Gazebo/Grey</name>
            <uri>file://media/materials/scripts/gazebo.material</uri>
          </script>
        </material>
      </visual>
      <visual name='lwr_7_link_fixed_joint_lump__tool_link_visual_1'>
        <pose frame=''>0 0 0 0 -0 0</pose>
        <geometry>
          <mesh>
            <scale>1 1 1</scale>
            <uri>model://lwr_end_eff/meshes/visual/tool.stl</uri>
          </mesh>
        </geometry>
        <material>
          <script>
            <uri>__default__</uri>
            <name>__default__</name>
          </script>
        </material>
      </visual>
      <velocity_decay/>
      <gravity>1</gravity>
      <velocity_decay/>
      <sensor name='my_contact' type='contact'>
        <plugin name='my_plugin' filename='libcontact.so'>
          <alwaysOn>1</alwaysOn>
          <updateRate>500</updateRate>
          <bumperTopicName>bumper</bumperTopicName>
          <frameName>tool_link</frameName>
        </plugin>
        <contact>
          <collision>tool_link_collision_collision</collision>
          <topic>__default_topic__</topic>
        </contact>
        <update_rate>500</update_rate>
        <pose frame=''>0 0 0 0 -0 0</pose>
      </sensor>
      <gravity>1</gravity>
      <velocity_decay/>
      <sensor name='gripper_contact_sensor' type='contact'>
        <always_on>1</always_on>
        <update_rate>500</update_rate>
        <contact>
          <collision>tool_link_collision_collision</collision>
          <topic>__default_topic__</topic>
        </contact>
        <plugin name='gripper_bumper' filename='libgazebo_ros_bumper.so'>
          <bumperTopicName>gripper_contact_sensor_state</bumperTopicName>
          <frameName>tool_link</frameName>
        </plugin>
        <pose frame=''>0 0 0 0 -0 0</pose>
      </sensor>
    </link>
    <joint name='lwr_a6_joint' type='revolute'>
      <child>lwr_7_link</child>
      <parent>lwr_6_link</parent>
      <axis>
        <xyz>0 0 1</xyz>
        <limit>
          <lower>-2.96706</lower>
          <upper>2.96706</upper>
          <effort>38</effort>
          <velocity>3.21141</velocity>
        </limit>
        <dynamics>
          <spring_reference>0</spring_reference>
          <spring_stiffness>0</spring_stiffness>
        </dynamics>
        <use_parent_model_frame>1</use_parent_model_frame>
      </axis>
    </joint>
    <static>0</static>
    <plugin name='gazebo_ros_controller' filename='libgazebo_ros_control.so'>
      <robotNamespace>lwr</robotNamespace>
    </plugin>
  </model>
</sdf>
